[
  {
    "timestamp": "2025-07-15T10:25:36.539048",
    "session_id": "20250715_102235",
    "level": "ERROR",
    "message": "Exception in context 'oauth_flow'",
    "exception_type": "TimeoutError",
    "exception_message": "OAuth flow timed out after 180 seconds. Please try again or check your browser.",
    "traceback": "Traceback (most recent call last):\n  File \"/home/ncacord/RaidAssist/auth_server.py\", line 210, in get_auth_code\n    raise TimeoutError(\n    ...<2 lines>...\n    )\nTimeoutError: OAuth flow timed out after 180 seconds. Please try again or check your browser.\n",
    "context_stack": [
      "authentication_check",
      "token_loading",
      "oauth_flow",
      "oauth_flow"
    ],
    "extra": {}
  },
  {
    "timestamp": "2025-07-15T10:25:36.540553",
    "session_id": "20250715_102235",
    "level": "ERROR",
    "message": "Exception in context 'oauth_flow'",
    "exception_type": "TimeoutError",
    "exception_message": "OAuth flow timed out after 180 seconds. Please try again or check your browser.",
    "traceback": "Traceback (most recent call last):\n  File \"/home/ncacord/RaidAssist/api/bungie.py\", line 136, in prompt_for_oauth_token\n    code = get_auth_code(auth_url, ssl_context=ssl_ctx)\n  File \"/home/ncacord/RaidAssist/auth_server.py\", line 210, in get_auth_code\n    raise TimeoutError(\n    ...<2 lines>...\n    )\nTimeoutError: OAuth flow timed out after 180 seconds. Please try again or check your browser.\n",
    "context_stack": [
      "authentication_check",
      "token_loading",
      "oauth_flow"
    ],
    "extra": {}
  },
  {
    "timestamp": "2025-07-15T10:25:36.549190",
    "session_id": "20250715_102235",
    "level": "ERROR",
    "message": "Test error message",
    "exception_type": "ValueError",
    "exception_message": "Test exception",
    "traceback": "Traceback (most recent call last):\n  File \"/home/ncacord/RaidAssist/tests/test_enhanced_systems.py\", line 79, in test_error_logging_with_exception\n    raise ValueError(\"Test exception\")\nValueError: Test exception\n",
    "context_stack": [
      "authentication_check"
    ],
    "extra": {}
  },
  {
    "timestamp": "2025-07-15T10:25:42.597373",
    "session_id": "20250715_102235",
    "level": "ERROR",
    "message": "Test error message",
    "exception_type": "ValueError",
    "exception_message": "Test exception",
    "traceback": "Traceback (most recent call last):\n  File \"/home/ncacord/RaidAssist/tests/test_systems.py\", line 79, in test_error_logging_with_exception\n    raise ValueError(\"Test exception\")\nValueError: Test exception\n",
    "context_stack": [
      "authentication_check"
    ],
    "extra": {}
  }
]